\question
 What will be the output of the following Python code?

def foo():
    try:
        return 1
    finally:
        return 2
k = foo()
print(k)

\begin{enumerate}
\item 1
\item 2
\item 3
\item error, there is more than one return statement in a single try-finally block
\end{enumerate}

